Workbook

Sheet Cover
B2: Harley-Davidson, Inc. (NYSE: HOG) - Short
B3: Squarepoint EDGE Stock Pitch - Financial model | Leen Bou Alia | October 2026
B5: Key outputs
B6: Current price | C6: =Valuation!C19 -> 26.95
B7: Price target (probability-weighted) | C7: =Valuation!C20 -> 21.11034
B8: Expected return to a short | C8: =Valuation!C21 -> 0.21668496
B9: Bear / Base / Bull value per share | C9: =TEXT(Valuation!C15,"$0.00")&" / "&TEXT(Valuation!D15,"$0.00")&" / "&TEXT(Valuation!E15,"$0.00") -> $12.43 / $18.78 / $43.12
B10: FY2026E EPS (Base) vs. consensus $0.68 | C10: =Base!S43 -> 0.55290489
B11: FY2027E EPS (Base) | C11: =Base!T43 -> 0.798078
B12: Signal | C12: =Valuation!C29 -> SHORT supported
B14: Colour legend (per competition prompt)
B15: Reported company data
B16: Formulas & calculations
B17: Participant assumptions
B18: Consensus / market estimates
B20: Structure
B21: Inputs - market data, guidance, common and scenario assumptions (edit red cells only)
B22: Historicals - 8 quarters (Q3'24-Q2'26) transcribed from SEC filings, with sources
B23: Base / Bear / Bull - integrated IS, BS, CF; unit drivers; ROIC; DCF & multiples SOTP (one sheet per scenario)
B24: Quarterly forecast Q3'26-Q4'27 (6 quarters) + annual FY2028E-FY2029E
B25: Assumptions - log of every input (live links) plus structural/methodology assumptions
B26: Valuation - probability-weighted scenarios, price target, comps, EPS & valuation sensitivities
... B29: fitted on Q1'25-Q2'26 (see Inputs). This captures Q4 under-absorption losses and operating leverage.

Sheet Historicals
A1: Harley-Davidson, Inc. - Reported historical data (as reported; $ thousands unless noted)
A2: Blue = reported company data, transcribed from SEC filings (8-K earnings releases and 10-Q). Quarterly cash flows derived as YTD differences. D&A and SBC from 10-Q cash flow statements as compiled by StockAnalysis.
A4: Line item | B4: Unit | C4: Q3'24 | D4: Q4'24 | E4: Q1'25 | F4: Q2'25 | G4: Q3'25 | H4: Q4'25 | I4: Q1'26 | J4: Q2'26
A5: Income statement (segment presentation)
A6: HDMC - Motorcycles revenue | B6: $000 | C6: 615628 | D6: 231470 | E6: 863863 | F6: 778051 | G6: 821864 | H6: 193882 | I6: 836294 | J6: 848057
A7: HDMC - Parts & accessories revenue | B7: $000 | C7: 174301 | D7: 117605 | E7: 143433 | F7: 186874 | G7: 167252 | H7: 116513 | I7: 142243 | J7: 176950
A8: HDMC - Apparel revenue | B8: $000 | C8: 55688 | D8: 54078 | E8: 57322 | F8: 55240 | G8: 56052 | H8: 47169 | I8: 57313 | J8: 56068
A9: HDMC - Licensing revenue | B9: $000 | C9: 3897 | D9: 4436 | E9: 3058 | F9: 5944 | G9: 5547 | H9: 7124 | I9: 6048 | J9: 6298
A10: HDMC - Other revenue | B10: $000 | C10: 26891 | D10: 12900 | E10: 13829 | F10: 17540 | G10: 23244 | H10: 14507 | I10: 13573 | J10: 16907
A11: HDMC gross profit | B11: $000 | C11: 263813 | D11: -3170 | E11: 315244 | F11: 298705 | G11: 283110 | H11: -30467 | I11: 266989 | J11: 304126
A12: HDMC operating expense | B12: $000 | C12: 208676 | D12: 210472 | E12: 198972 | F12: 237389 | G12: 228991 | H12: 229970 | I12: 248064 | J12: 231788
A13: LiveWire revenue | B13: $000 | C13: 4808 | D13: 10400 | E13: 2743 | F13: 6011 | G13: 5563 | H13: 11354 | I13: 5116 | J13: 9114
A14: LiveWire gross profit | B14: $000 | C14: -1180 | D14: -5608 | E14: -1781 | F14: 162 | G14: -2271 | H14: -545 | I14: -535 | J14: -48
A15: LiveWire operating expense | B15: $000 | C15: 24905 | D15: 20538 | E15: 18028 | F15: 18815 | G15: 15910 | H15: 17829 | I15: 17136 | J15: 17879
A16: HDFS revenue | B16: $000 | C16: 269482 | D16: 256720 | E16: 244961 | F16: 257438 | G16: 261188 | H16: 105609 | I16: 111944 | J16: 117043
A17: HDFS operating income | B17: $000 | C17: 76744 | D17: 46440 | E17: 64036 | F17: 69773 | G17: 438820 | H17: -82247 | I17: 22240 | J17: 21599
... A25: Dividends per share | B25: $ | C25: 0.1725 | D25: 0.1725 | E25: 0.18 | F25: 0.18 | G25: 0.18 | H25: 0.18 | I25: 0.1875 | J25: 0.1875
A26: Units
A27: HDMC worldwide shipments | B27: units | C27: 27520 | D27: 14010 | E27: 38601 | F27: 35837 | G27: 36524 | H27: 13515 | I27: 37295 | J27: 39209
A28: Grand American Touring (incl. Trike) | B28: units | C28: 15493 | D28: 5563 | E28: 23678 | F28: 18080 | G28: 22035 | H28: 5459 | I28: 21520 | J28: 19641
A29: Cruiser | B29: units | C29: 9610 | D29: 6524 | E29: 11860 | F29: 13110 | G29: 10551 | H29: 5651 | I29: 10659 | J29: 13550
A30: Sport & Lightweight | B30: units | C30: 1770 | D30: 1508 | E30: 2108 | F30: 3188 | G30: 2628 | H30: 1714 | I30: 3731 | J30: 4617
A31: Adventure Touring | B31: units | C31: 647 | D31: 415 | E31: 955 | F31: 1459 | G31: 1310 | H31: 691 | I31: 1385 | J31: 1401
A32: Retail sales - North America | B32: units | C32: 24573 | D32: 15127 | E32: 20892 | F32: 28931 | G32: 23462 | H32: 15847 | I32: 23803 | J32: 29751
A33: Retail sales - EMEA | B33: units | C33: 6054 | D33: 4749 | E33: 5175 | F33: 7621 | G33: 5033 | H33: 3625 | I33: 5034 | J33: 6959
A34: Retail sales - Asia Pacific | B34: units | C34: 4832 | D34: 5025 | E34: 4362 | F34: 4967 | G34: 4667 | H34: 4979 | I34: 3967 | J34: 4990
A35: Retail sales - Latin America | B35: units | C35: 707 | D35: 759 | E35: 581 | F35: 735 | G35: 822 | H35: 836 | I35: 703 | J35: 767
A36: Global dealer inventory, YoY change | B36: % | G36: -0.13 | H36: -0.17 | I36: -0.22 | J36: -0.17
A37: Balance sheet (period end)
A38: Cash and cash equivalents | B38: $000 | C38: 2243910 | D38: 1589608 | E38: 1931175 | F38: 1587664 | G38: 1775038 | H38: 3091744 | I38: 1805068 | J38: 1895789
A39: Restricted cash (current) | B39: $000 | C39: 147910 | D39: 135661 | E39: 150132 | F39: 149782 | G39: 51530 | H39: 0 | I39: 0 | J39: 0
A40: Accounts receivable, net | B40: $000 | C40: 307701 | D40: 234315 | E40: 313334 | F40: 325756 | G40: 305010 | H40: 225760 | I40: 285786 | J40: 301788
A41: Finance receivables held for sale | B41: $000 | C41: 0 | D41: 0 | E41: 0 | F41: 0 | G41: 4080885 | H41: 264238 | I41: 426792 | J41: 545761
A42: Finance receivables HFI - current | B42: $000 | C42: 2300551 | D42: 2031496 | E42: 2286672 | F42: 2127866 | G42: 1221348 | H42: 981926 | I42: 1187550 | J42: 1094533
A43: Inventories, net | B43: $000 | C43: 681864 | D43: 745793 | E43: 712312 | F43: 630287 | G43: 512186 | H43: 730898 | I43: 622189 | J43: 500935
A44: Other current assets | B44: $000 | C44: 208000 | D44: 259764 | E44: 253687 | F44: 327260 | G44: 297444 | H44: 292383 | I44: 415301 | J44: 250420
A45: Finance receivables HFI - long-term | B45: $000 | C45: 5499836 | D45: 5256798 | E45: 5112935 | F45: 5198356 | G45: 662201 | H45: 719060 | I45: 827061 | J45: 1004886
A46: Other long-term assets (incl. PP&E, pension, goodwill) | B46: $000 | C46: 1636887 | D46: 1628144 | E46: 1622134 | F46: 1703474 | G46: 1660742 | H46: 1738806 | I46: 1675914 | J46: 1651753
A47: Total assets | B47: $000 | C47: 13026659 | D47: 11881579 | E47: 12382381 | F47: 12050445 | G47: 10566384 | H47: 8044815 | I47: 7245661 | J47: 7245865
A48: Accounts payable & accrued liabilities | B48: $000 | C48: 931971 | D48: 892678 | E48: 1105802 | F48: 1040616 | G48: 971411 | H48: 1061194 | I48: 1232554 | J48: 1033420
...

Sheet Inputs
B1: Inputs & assumptions
B2: Red = analyst assumption (edit these) | Purple = consensus / market data | Black = formula
B4: Market & consensus data
B5: HOG share price | C5: $ | E5: 26.95 | G5: Updated 7-Oct-2026 (was $26.19 close 5-Oct per StockAnalysis). Update again on submission day.
B6: Shares outstanding | C6: m | E6: 104.07 | G6: StockAnalysis, latest reported.
B7: Consensus FY2026 EPS | C7: $ | E7: 0.68 | G7: TIKR / Citi upgrade coverage, Oct-2026.
B8: Consensus FY2026 revenue growth | C8: % | E8: 0.06 | G8: TIKR, Oct-2026 (motorcycles & related).
B9: Consensus FY2027 revenue growth | C9: % | E9: 0.04 | G9: TIKR, Oct-2026.
B10: Consensus average price target | C10: $ | E10: 28.18 | G10: StockAnalysis, Oct-2026 (Hold).
B11: Citi price target (upgrade to Buy, 5-Oct-2026) | C11: $ | E11: 33 | G11: Citi Research via GuruFocus/TIKR.
B12: Short interest, % of shares outstanding | C12: % | E12: 0.1779 | G12: StockAnalysis; 11.2 days to cover.
B13: Enterprise value (market) | C13: $m | E13: 3720 | G13: StockAnalysis, 5-Oct-2026.
B14: EV / EBITDA (trailing, market) | C14: x | E14: 8.66 | G14: StockAnalysis, 5-Oct-2026.
B15: Price / book (market) | C15: x | E15: 0.82 | G15: StockAnalysis, 5-Oct-2026 (static; comps table recomputes P/B at current price).
B16: HOG net debt & other claims used in market EV | C16: $m | E16: 990 | G16: EV $3.72bn - mkt cap $2.73bn, StockAnalysis 5-Oct-2026. Held constant when price changes.
... B19: HOG annual dividend per share | C19: $ | E19: 0.75 | G19: 4 x $0.1875 quarterly (Q2'26 8-K).
B21: Company guidance (FY2026, Q2'26 release)
B22: HDMC wholesale shipments - low | C22: units | E22: 133500 | G22: Q2'26 8-K Ex.99.1
B23: HDMC wholesale shipments - high | C23: units | E23: 138500 | G23: Same range guided for retail.
B24: HDMC operating income - low | C24: $m | E24: 10
B25: HDMC operating income - high | C25: $m | E25: 50
B26: Long-term deposits at Jun-26 (in Other LT liabilities) | C26: $m | E26: 250.043 | G26: Q2'26 10-Q balance sheet.
B28: Common assumptions (all scenarios)
B29: Effective tax rate | C29: % | E29: 0.23 | G29: ~FY25 normalised rate.
B30: Other income, net (per quarter) | C30: $m | E30: 12 | G30: H1'26 run-rate ~$12.3m/qtr (pension income).
B31: Investment income (per quarter) | C31: $m | E31: 9 | G31: Lower cash balances after buybacks/debt paydown.
B32: Corporate interest expense (per quarter) | C32: $m | E32: 3.6 | G32: H1'26 run-rate.
B33: D&A (per quarter) | C33: $m | E33: 43 | G33: H1'26 avg $43.4m.
B34: Stock-based compensation (per quarter) | C34: $m | E34: 9 | G34: H1'26 avg $9.0m.
B35: NCI share of LiveWire operating loss | C35: % | E35: 0.05 | G35: H1'26: $1.5m NCI loss / $35.6m LW loss.
B36: FY2026 capex | C36: $m | E36: 190 | G36: Guidance $175-200m; H1'26 actual $44.7m.
B37: Capex per year, FY2027+ | C37: $m | E37: 185
B38: Q3 share of H2'26 shipments | C38: % | E38: 0.6 | G38: Q3'25 was 73% of H2'25 shipments, but Q4'25 was depressed by destocking.
B39: FY2027 shipment seasonality - Q1 | C39: % | E39: 0.28 | G39: Q4 kept low (northern off-season).
B40: FY2027 shipment seasonality - Q2 | C40: % | E40: 0.29
B41: FY2027 shipment seasonality - Q3 | C41: % | E41: 0.26
B42: FY2027 shipment seasonality - Q4 | C42: % | E42: =1-E39-E40-E41 -> 0.17 | G42: Plug so shares sum to 100%.
B43: HDMC fixed manufacturing cost inflation, per year | C43: % | E43: 0.02
B44: Finance receivables growth, per year | C44: % | E44: 0 | G44: Capital-light HDFS: originations sold to KKR/PIMCO vehicle.
B45: Dividend per share growth, per year | C45: % | E45: 0.04 | G45: Recent increases ~4%/yr.
...

Sheet Assumptions
B1: Assumptions log - every input used by the model, with rationale and source
B2: Values link live to the Inputs tab (edit them there). Colour of the value follows the prompt: red = analyst assumption, purple = market/consensus, blue = reported, black = derived.
A4: # | B4: Assumption | C4: Unit | D4: Type | E4: Value / Base | F4: Bear | G4: Base | H4: Bull | I4: Rationale & source
A5: 1 | B5: HOG share price | C5: $ | D5: Market / consensus | E5: =Inputs!E5 -> 26.95 | I5: Updated 7-Oct-2026 (was $26.19 close 5-Oct per StockAnalysis). Update again on submission day.
A6: 2 | B6: Shares outstanding | C6: m | D6: Market / consensus | E6: =Inputs!E6 -> 104.07 | I6: StockAnalysis, latest reported.
A7: 3 | B7: Consensus FY2026 EPS | C7: $ | D7: Market / consensus | E7: =Inputs!E7 -> 0.68 | I7: TIKR / Citi upgrade coverage, Oct-2026.
A8: 4 | B8: Consensus FY2026 revenue growth | C8: % | D8: Market / consensus | E8: =Inputs!E8 -> 0.06 | I8: TIKR, Oct-2026 (motorcycles & related).
A9: 5 | B9: Consensus FY2027 revenue growth | C9: % | D9: Market / consensus | E9: =Inputs!E9 -> 0.04 | I9: TIKR, Oct-2026.
A10: 6 | B10: Consensus average price target | C10: $ | D10: Market / consensus | E10: =Inputs!E10 -> 28.18 | I10: StockAnalysis, Oct-2026 (Hold).
A11: 7 | B11: Citi price target (upgrade to Buy, 5-Oct-2026) | C11: $ | D11: Market / consensus | E11: =Inputs!E11 -> 33 | I11: Citi Research via GuruFocus/TIKR.
A12: 8 | B12: Short interest, % of shares outstanding | C12: % | D12: Market / consensus | E12: =Inputs!E12 -> 0.1779 | I12: StockAnalysis; 11.2 days to cover.
A13: 9 | B13: Enterprise value (market) | C13: $m | D13: Market / consensus | E13: =Inputs!E13 -> 3720 | I13: StockAnalysis, 5-Oct-2026.
A14: 10 | B14: EV / EBITDA (trailing, market) | C14: x | D14: Market / consensus | E14: =Inputs!E14 -> 8.66 | I14: StockAnalysis, 5-Oct-2026.
A15: 11 | B15: Price / book (market) | C15: x | D15: Market / consensus | E15: =Inputs!E15 -> 0.82 | I15: StockAnalysis, 5-Oct-2026 (static; comps table recomputes P/B at current price).
A16: 12 | B16: HOG net debt & other claims used in market EV | C16: $m | D16: Market / consensus | E16: =Inputs!E16 -> 990 | I16: EV $3.72bn - mkt cap $2.73bn, StockAnalysis 5-Oct-2026. Held constant when price changes.
... A19: 15 | B19: HOG annual dividend per share | C19: $ | D19: Reported / guidance | E19: =Inputs!E19 -> 0.75 | I19: 4 x $0.1875 quarterly (Q2'26 8-K).
A20: 16 | B20: HDMC wholesale shipments - low | C20: units | D20: Reported / guidance | E20: =Inputs!E22 -> 133500 | I20: Q2'26 8-K Ex.99.1
A21: 17 | B21: HDMC wholesale shipments - high | C21: units | D21: Reported / guidance | E21: =Inputs!E23 -> 138500 | I21: Same range guided for retail.
A22: 18 | B22: HDMC operating income - low | C22: $m | D22: Reported / guidance | E22: =Inputs!E24 -> 10
A23: 19 | B23: HDMC operating income - high | C23: $m | D23: Reported / guidance | E23: =Inputs!E25 -> 50
A24: 20 | B24: Long-term deposits at Jun-26 (in Other LT liabilities) | C24: $m | D24: Reported / guidance | E24: =Inputs!E26 -> 250.043 | I24: Q2'26 10-Q balance sheet.
A25: 21 | B25: Effective tax rate | C25: % | D25: Analyst assumption | E25: =Inputs!E29 -> 0.23 | I25: ~FY25 normalised rate.
A26: 22 | B26: Other income, net (per quarter) | C26: $m | D26: Analyst assumption | E26: =Inputs!E30 -> 12 | I26: H1'26 run-rate ~$12.3m/qtr (pension income).
A27: 23 | B27: Investment income (per quarter) | C27: $m | D27: Analyst assumption | E27: =Inputs!E31 -> 9 | I27: Lower cash balances after buybacks/debt paydown.
A28: 24 | B28: Corporate interest expense (per quarter) | C28: $m | D28: Analyst assumption | E28: =Inputs!E32 -> 3.6 | I28: H1'26 run-rate.
A29: 25 | B29: D&A (per quarter) | C29: $m | D29: Analyst assumption | E29: =Inputs!E33 -> 43 | I29: H1'26 avg $43.4m.
A30: 26 | B30: Stock-based compensation (per quarter) | C30: $m | D30: Analyst assumption | E30: =Inputs!E34 -> 9 | I30: H1'26 avg $9.0m.
A31: 27 | B31: NCI share of LiveWire operating loss | C31: % | D31: Analyst assumption | E31: =Inputs!E35 -> 0.05 | I31: H1'26: $1.5m NCI loss / $35.6m LW loss.
A32: 28 | B32: FY2026 capex | C32: $m | D32: Analyst assumption | E32: =Inputs!E36 -> 190 | I32: Guidance $175-200m; H1'26 actual $44.7m.
A33: 29 | B33: Capex per year, FY2027+ | C33: $m | D33: Analyst assumption | E33: =Inputs!E37 -> 185
A34: 30 | B34: Q3 share of H2'26 shipments | C34: % | D34: Analyst assumption | E34: =Inputs!E38 -> 0.6 | I34: Q3'25 was 73% of H2'25 shipments, but Q4'25 was depressed by destocking.
A35: 31 | B35: FY2027 shipment seasonality - Q1 | C35: % | D35: Analyst assumption | E35: =Inputs!E39 -> 0.28 | I35: Q4 kept low (northern off-season).
A36: 32 | B36: FY2027 shipment seasonality - Q2 | C36: % | D36: Analyst assumption | E36: =Inputs!E40 -> 0.29
A37: 33 | B37: FY2027 shipment seasonality - Q3 | C37: % | D37: Analyst assumption | E37: =Inputs!E41 -> 0.26
A38: 34 | B38: FY2027 shipment seasonality - Q4 | C38: % | D38: Derived (formula) | E38: =Inputs!E42 -> 0.17 | I38: Plug so shares sum to 100%.
A39: 35 | B39: HDMC fixed manufacturing cost inflation, per year | C39: % | D39: Analyst assumption | E39: =Inputs!E43 -> 0.02
A40: 36 | B40: Finance receivables growth, per year | C40: % | D40: Analyst assumption | E40: =Inputs!E44 -> 0 | I40: Capital-light HDFS: originations sold to KKR/PIMCO vehicle.
A41: 37 | B41: Dividend per share growth, per year | C41: % | D41: Analyst assumption | E41: =Inputs!E45 -> 0.04 | I41: Recent increases ~4%/yr.
A42: 38 | B42: Non-Financial Services entities: cash & equivalents, Jun-26 | C42: $m | D42: Reported / guidance | E42: =Inputs!E46 -> 1283.3 | I42: Q2'26 10-Q, Note 17 Supplemental Consolidating Data (HDMC + LiveWire legal entities). Financial Services entities hold the other $612.5m.
A43: 39 | B43: Non-Financial Services entities: debt, Jun-26 | C43: $m | D43: Reported / guidance | E43: =Inputs!E47 -> 297.342 | I43: Q2'26 10-Q, Note 17: long-term debt only ($300m 4.625% senior notes due 2045); no short-term debt.
...

Sheet Valuation
B1: Valuation summary, scenarios & sensitivities
B3: Probability-weighted scenario analysis | C3: Bear | D3: Base | E3: Bull | F3: Prob.-wtd.
B4: Probability | C4: =Inputs!$D$65 -> 0.4 | D4: =Inputs!$E$65 -> 0.4 | E4: =Inputs!$F$65 -> 0.2 | F4: =SUM(C4:E4) -> 1
B5: FY2027E retail units | C5: =Bear!T6 -> 126793.53 | D5: =Base!T6 -> 138992 | E5: =Bull!T6 -> 145586.15
B6: FY2027E shipments | C6: =Bear!T9 -> 121721.79 | D6: =Base!T9 -> 140381.92 | E6: =Bull!T9 -> 148497.87
B7: FY2027E HDMC revenue ($m) | C7: =Bear!T21 -> 3367.6301 | D7: =Base!T21 -> 3959.1621 | E7: =Bull!T21 -> 4255.8069
B8: FY2027E HDMC gross margin | C8: =Bear!T24 -> 0.19615115 | D8: =Base!T24 -> 0.24869408 | E8: =Bull!T24 -> 0.27859212
B9: FY2027E HDMC operating income ($m) | C9: =Bear!T26 -> -306.38757 | D9: =Base!T26 -> 31.78356 | E9: =Bull!T26 -> 246.82126 | F9: =SUMPRODUCT($C$4:$E$4,C9:E9) -> -60.47735
B10: FY2026E EPS | C10: =Bear!S43 -> -0.23066149 | D10: =Base!S43 -> 0.55290489 | E10: =Bull!S43 -> 1.1123279 | F10: =SUMPRODUCT($C$4:$E$4,C10:E10) -> 0.35136294
B11: FY2027E EPS | C11: =Bear!T43 -> -1.9294901 | D11: =Base!T43 -> 0.798078 | E11: =Bull!T43 -> 2.6564773 | F11: =SUMPRODUCT($C$4:$E$4,C11:E11) -> 0.078730613
B12: FY2027E industrial EBITDA ($m) | C12: =Bear!T49 -> -214.38757 | D12: =Base!T49 -> 138.78356 | E12: =Bull!T49 -> 363.82126
B13: Value per share - multiples SOTP | C13: =Bear!T108 -> 12.432933 | D13: =Base!T108 -> 23.408504 | E13: =Bull!T108 -> 43.635982
B14: Value per share - DCF SOTP | C14: =Bear!T116 -> 12.432933 | D14: =Base!T116 -> 14.156267 | E14: =Bull!T116 -> 42.606146
B15: Scenario value per share (blended) | C15: =Bear!T117 -> 12.432933 | D15: =Base!T117 -> 18.782385 | E15: =Bull!T117 -> 43.121064 | F15: =SUMPRODUCT($C$4:$E$4,C15:E15) -> 21.11034
B16: vs. current price | C16: =Bear!T118 -> -0.53866667 | D16: =Base!T118 -> -0.30306548 | E16: =Bull!T118 -> 0.60003948 | F16: =SUMPRODUCT($C$4:$E$4,C16:E16) -> -0.21668496
B18: Recommendation | C18: Value
B19: Current price | C19: =Inputs!$E$5 -> 26.95
B20: Price target (probability-weighted) | C20: =F15 -> 21.11034
B21: Expected return to a SHORT position (excl. dividends & borrow) | C21: =-(C20/C19-1) -> 0.21668496
B22: Downside to bear case | C22: =C15/Inputs!$E$5-1 -> -0.53866667
B23: Upside to bull case (risk to short) | C23: =E15/Inputs!$E$5-1 -> 0.60003948
B24: Reward / risk (bear downside / bull upside) | C24: =-C22/C23 -> 0.89771871
B25: Dividend carry cost (12m) | C25: =Base!T45/Inputs!$E$5 -> 0.028942486
B26: Consensus average price target | C26: =Inputs!$E$10 -> 28.18
B27: Citi price target | C27: =Inputs!$E$11 -> 33
B28: Model FY2026E EPS (prob.-wtd.) vs. consensus | C28: =F10/Inputs!$E$7-1 -> -0.48328979
B29: Signal | C29: =IF(C21>=Inputs!$E$54,"SHORT supported",IF(C21>0,"Marginal short","Short NOT supported at current price")) -> SHORT supported
B31: Peer comparables (market data, Oct-2026) | C31: Price | D31: Mkt cap $bn | E31: EV $bn | F31: EV/EBITDA | G31: Fwd P/E | H31: P/B | I31: Div. yield
B32: Polaris (PII) | C32: 53.71 | D32: 3.06 | E32: 4.81 | F32: 9.78 | G32: 19.14 | H32: 3.65 | I32: 0.0506
B33: BRP (DOO) | C33: 56.1 | D33: 3.99 | E33: 5.65 | F33: 8.06 | G33: 16.9 | H33: 16.39 | I33: 0.0124
B34: Harley-Davidson (HOG) | C34: =Inputs!$E$5 -> 26.95 | D34: =Inputs!$E$5*Inputs!$E$6/1000 -> 2.8046865 | E34: =D34+Inputs!$E$16/1000 -> 3.7946865 | F34: =E34*1000/Inputs!$E$17 -> 8.8330691 | G34: =Inputs!$E$5/Inputs!$E$18 -> 18.793584 | H34: =Inputs!$E$5*Inputs!$E$6/(Historicals!J54/1000) -> 0.90008646 | I34: =Inputs!$E$19/Inputs!$E$5 -> 0.027829314
B35: Peer average (PII, BRP) | F35: =AVERAGE(F32:F33) -> 8.92 | G35: =AVERAGE(G32:G33) -> 18.02 | H35: =AVERAGE(H32:H33) -> 10.02 | I35: =AVERAGE(I32:I33) -> 0.0315
B36: Peers: StockAnalysis.com (S&P Global data), 3-6 Oct 2026, static. HOG row recomputes at the Inputs price (P/B on Jun-26 total equity). Eicher / Piaggio excluded (non-US listings).
B38: Sensitivity (Base case): FY2027E EPS | D38: Contribution margin vs. Base
B39: FY2027 retail growth (rows) / CM change (cols) | C39: -0.03 | D39: -0.02 | E39: -0.01 | F39: 0 | G39: 0.01 | H39: 0.02
B40: -0.08 | C40: =(Base!$T$41+((Base!$T$21*(1+$B40)/(1+Inputs!$E$67))*(Inputs!$E$57+Inputs!$E$80+C$39)-Base!$T$21*(Inputs!$E$57+Inputs!$E$80))*(1-Inputs!$E$29))/Base!$T$42 -> -1.2524611 | D40: =(Base!$T$41+((Base!$T$21*(1+$B40)/(1+Inputs!$E$67))*(Inputs!$E$57+Inputs!$E$80+D$39)-Base!$T$21*(Inputs!$E$57+Inputs!$E$80))*(1-Inputs!$E$29))/Base!$T$42 -> -0.97991914 | E40: =(Base!$T$41+((Base!$T$21*(1+$B40)/(1+Inputs!$E$67))*(Inputs!$E$57+Inputs!$E$80+E$39)-Base!$T$21*(Inputs!$E$57+Inputs!$E$80))*(1-Inputs!$E$29))/Base!$T$42 -> -0.70737721 | F40: =(Base!$T$41+((Base!$T$21*(1+$B40)/(1+Inputs!$E$67))*(Inputs!$E$57+Inputs!$E$80+F$39)-Base!$T$21*(Inputs!$E$57+Inputs!$E$80))*(1-Inputs!$E$29))/Base!$T$42 -> -0.43483529 | G40: =(Base!$T$41+((Base!$T$21*(1+$B40)/(1+Inputs!$E$67))*(Inputs!$E$57+Inputs!$E$80+G$39)-Base!$T$21*(Inputs!$E$57+Inputs!$E$80))*(1-Inputs!$E$29))/Base!$T$42 -> -0.16229336 | H40: =(Base!$T$41+((Base!$T$21*(1+$B40)/(1+Inputs!$E$67))*(Inputs!$E$57+Inputs!$E$80+H$39)-Base!$T$21*(Inputs!$E$57+Inputs!$E$80))*(1-Inputs!$E$29))/Base!$T$42 -> 0.11024856
B41: -0.05 | C41: =(Base!$T$41+((Base!$T$21*(1+$B41)/(1+Inputs!$E$67))*(Inputs!$E$57+Inputs!$E$80+C$39)-Base!$T$21*(Inputs!$E$57+Inputs!$E$80))*(1-Inputs!$E$29))/Base!$T$42 -> -0.86815167 | D41: =(Base!$T$41+((Base!$T$21*(1+$B41)/(1+Inputs!$E$67))*(Inputs!$E$57+Inputs!$E$80+D$39)-Base!$T$21*(Inputs!$E$57+Inputs!$E$80))*(1-Inputs!$E$29))/Base!$T$42 -> -0.58672251 | E41: =(Base!$T$41+((Base!$T$21*(1+$B41)/(1+Inputs!$E$67))*(Inputs!$E$57+Inputs!$E$80+E$39)-Base!$T$21*(Inputs!$E$57+Inputs!$E$80))*(1-Inputs!$E$29))/Base!$T$42 -> -0.30529335 | F41: =(Base!$T$41+((Base!$T$21*(1+$B41)/(1+Inputs!$E$67))*(Inputs!$E$57+Inputs!$E$80+F$39)-Base!$T$21*(Inputs!$E$57+Inputs!$E$80))*(1-Inputs!$E$29))/Base!$T$42 -> -0.023864191 | G41: =(Base!$T$41+((Base!$T$21*(1+$B41)/(1+Inputs!$E$67))*(Inputs!$E$57+Inputs!$E$80+G$39)-Base!$T$21*(Inputs!$E$57+Inputs!$E$80))*(1-Inputs!$E$29))/Base!$T$42 -> 0.25756497 | H41: =(Base!$T$41+((Base!$T$21*(1+$B41)/(1+Inputs!$E$67))*(Inputs!$E$57+Inputs!$E$80+H$39)-Base!$T$21*(Inputs!$E$57+Inputs!$E$80))*(1-Inputs!$E$29))/Base!$T$42 -> 0.53899413
B42: -0.02 | C42: =(Base!$T$41+((Base!$T$21*(1+$B42)/(1+Inputs!$E$67))*(Inputs!$E$57+Inputs!$E$80+C$39)-Base!$T$21*(Inputs!$E$57+Inputs!$E$80))*(1-Inputs!$E$29))/Base!$T$42 -> -0.48384229 | D42: =(Base!$T$41+((Base!$T$21*(1+$B42)/(1+Inputs!$E$67))*(Inputs!$E$57+Inputs!$E$80+D$39)-Base!$T$21*(Inputs!$E$57+Inputs!$E$80))*(1-Inputs!$E$29))/Base!$T$42 -> -0.19352589 | E42: =(Base!$T$41+((Base!$T$21*(1+$B42)/(1+Inputs!$E$67))*(Inputs!$E$57+Inputs!$E$80+E$39)-Base!$T$21*(Inputs!$E$57+Inputs!$E$80))*(1-Inputs!$E$29))/Base!$T$42 -> 0.096790509 | F42: =(Base!$T$41+((Base!$T$21*(1+$B42)/(1+Inputs!$E$67))*(Inputs!$E$57+Inputs!$E$80+F$39)-Base!$T$21*(Inputs!$E$57+Inputs!$E$80))*(1-Inputs!$E$29))/Base!$T$42 -> 0.38710691 | G42: =(Base!$T$41+((Base!$T$21*(1+$B42)/(1+Inputs!$E$67))*(Inputs!$E$57+Inputs!$E$80+G$39)-Base!$T$21*(Inputs!$E$57+Inputs!$E$80))*(1-Inputs!$E$29))/Base!$T$42 -> 0.6774233 | H42: =(Base!$T$41+((Base!$T$21*(1+$B42)/(1+Inputs!$E$67))*(Inputs!$E$57+Inputs!$E$80+H$39)-Base!$T$21*(Inputs!$E$57+Inputs!$E$80))*(1-Inputs!$E$29))/Base!$T$42 -> 0.9677397
B43: 0.01 | C43: =(Base!$T$41+((Base!$T$21*(1+$B43)/(1+Inputs!$E$67))*(Inputs!$E$57+Inputs!$E$80+C$39)-Base!$T$21*(Inputs!$E$57+Inputs!$E$80))*(1-Inputs!$E$29))/Base!$T$42 -> -0.099532899 | D43: =(Base!$T$41+((Base!$T$21*(1+$B43)/(1+Inputs!$E$67))*(Inputs!$E$57+Inputs!$E$80+D$39)-Base!$T$21*(Inputs!$E$57+Inputs!$E$80))*(1-Inputs!$E$29))/Base!$T$42 -> 0.19967074 | E43: =(Base!$T$41+((Base!$T$21*(1+$B43)/(1+Inputs!$E$67))*(Inputs!$E$57+Inputs!$E$80+E$39)-Base!$T$21*(Inputs!$E$57+Inputs!$E$80))*(1-Inputs!$E$29))/Base!$T$42 -> 0.49887437 | F43: =(Base!$T$41+((Base!$T$21*(1+$B43)/(1+Inputs!$E$67))*(Inputs!$E$57+Inputs!$E$80+F$39)-Base!$T$21*(Inputs!$E$57+Inputs!$E$80))*(1-Inputs!$E$29))/Base!$T$42 -> 0.798078 | G43: =(Base!$T$41+((Base!$T$21*(1+$B43)/(1+Inputs!$E$67))*(Inputs!$E$57+Inputs!$E$80+G$39)-Base!$T$21*(Inputs!$E$57+Inputs!$E$80))*(1-Inputs!$E$29))/Base!$T$42 -> 1.0972816 | H43: =(Base!$T$41+((Base!$T$21*(1+$B43)/(1+Inputs!$E$67))*(Inputs!$E$57+Inputs!$E$80+H$39)-Base!$T$21*(Inputs!$E$57+Inputs!$E$80))*(1-Inputs!$E$29))/Base!$T$42 -> 1.3964853
B44: 0.04 | C44: =(Base!$T$41+((Base!$T$21*(1+$B44)/(1+Inputs!$E$67))*(Inputs!$E$57+Inputs!$E$80+C$39)-Base!$T$21*(Inputs!$E$57+Inputs!$E$80))*(1-Inputs!$E$29))/Base!$T$42 -> 0.28477649 | D44: =(Base!$T$41+((Base!$T$21*(1+$B44)/(1+Inputs!$E$67))*(Inputs!$E$57+Inputs!$E$80+D$39)-Base!$T$21*(Inputs!$E$57+Inputs!$E$80))*(1-Inputs!$E$29))/Base!$T$42 -> 0.59286736 | E44: =(Base!$T$41+((Base!$T$21*(1+$B44)/(1+Inputs!$E$67))*(Inputs!$E$57+Inputs!$E$80+E$39)-Base!$T$21*(Inputs!$E$57+Inputs!$E$80))*(1-Inputs!$E$29))/Base!$T$42 -> 0.90095823 | F44: =(Base!$T$41+((Base!$T$21*(1+$B44)/(1+Inputs!$E$67))*(Inputs!$E$57+Inputs!$E$80+F$39)-Base!$T$21*(Inputs!$E$57+Inputs!$E$80))*(1-Inputs!$E$29))/Base!$T$42 -> 1.2090491 | G44: =(Base!$T$41+((Base!$T$21*(1+$B44)/(1+Inputs!$E$67))*(Inputs!$E$57+Inputs!$E$80+G$39)-Base!$T$21*(Inputs!$E$57+Inputs!$E$80))*(1-Inputs!$E$29))/Base!$T$42 -> 1.51714 | H44: =(Base!$T$41+((Base!$T$21*(1+$B44)/(1+Inputs!$E$67))*(Inputs!$E$57+Inputs!$E$80+H$39)-Base!$T$21*(Inputs!$E$57+Inputs!$E$80))*(1-Inputs!$E$29))/Base!$T$42 -> 1.8252308
...

Sheet Base
A1: Harley-Davidson (HOG) - integrated model: BASE CASE ($ millions unless noted)
A2: Blue = reported | Black = formula | Red = assumption (see Inputs) | Purple = consensus/market. Shaded columns = forecast.
C4: Q3'24 | D4: Q4'24 | E4: Q1'25 | F4: Q2'25 | G4: Q3'25 | H4: Q4'25 | I4: Q1'26 | J4: Q2'26 | K4: Q3'26E | L4: Q4'26E | M4: Q1'27E | N4: Q2'27E | O4: Q3'27E | P4: Q4'27E | R4: FY2025A | S4: FY2026E | T4: FY2027E | U4: FY2028E | V4: FY2029E
A5: Unit drivers
A6: Retail sales - worldwide | B6: units | C6: =Historicals!C32+Historicals!C33+Historicals!C34+Historicals!C35 -> 36166 | D6: =Historicals!D32+Historicals!D33+Historicals!D34+Historicals!D35 -> 25660 | E6: =Historicals!E32+Historicals!E33+Historicals!E34+Historicals!E35 -> 31010 | F6: =Historicals!F32+Historicals!F33+Historicals!F34+Historicals!F35 -> 42254 | G6: =Historicals!G32+Historicals!G33+Historicals!G34+Historicals!G35 -> 33984 | H6: =Historicals!H32+Historicals!H33+Historicals!H34+Historicals!H35 -> 25287 | I6: =Historicals!I32+Historicals!I33+Historicals!I34+Historicals!I35 -> 33507 | J6: =Historicals!J32+Historicals!J33+Historicals!J34+Historicals!J35 -> 42467 | K6: =G6*(1+Inputs!$E$66) -> 35343.36 | L6: =H6*(1+Inputs!$E$66) -> 26298.48 | M6: =I6*(1+Inputs!$E$67) -> 33842.07 | N6: =J6*(1+Inputs!$E$67) -> 42891.67 | O6: =K6*(1+Inputs!$E$67) -> 35696.794 | P6: =L6*(1+Inputs!$E$67) -> 26561.465 | R6: =SUM(E6:H6) -> 132535 | S6: =SUM(I6:L6) -> 137615.84 | T6: =SUM(M6:P6) -> 138992 | U6: =T6*(1+Inputs!$E$68) -> 138992 | V6: =U6*(1+Inputs!$E$69) -> 138992
A7: of which North America | B7: units | C7: =Historicals!C32 -> 24573 | D7: =Historicals!D32 -> 15127 | E7: =Historicals!E32 -> 20892 | F7: =Historicals!F32 -> 28931 | G7: =Historicals!G32 -> 23462 | H7: =Historicals!H32 -> 15847 | I7: =Historicals!I32 -> 23803 | J7: =Historicals!J32 -> 29751 | R7: =SUM(E7:H7) -> 89132
A8: Retail growth YoY | B8: % | G8: =G6/C6-1 -> -0.060332909 | H8: =H6/D6-1 -> -0.014536243 | I8: =I6/E6-1 -> 0.080522412 | J8: =J6/F6-1 -> 0.0050409429 | K8: =K6/G6-1 -> 0.04 | L8: =L6/H6-1 -> 0.04 | M8: =M6/I6-1 -> 0.01 | N8: =N6/J6-1 -> 0.01 | ... P8: =P6/L6-1 -> 0.01 | S8: =S6/R6-1 -> 0.038335836 | T8: =T6/S6-1 -> 0.01 | U8: =U6/T6-1 -> 0 | V8: =V6/U6-1 -> 0
A9: HDMC shipments - worldwide | B9: units | C9: =Historicals!C27 -> 27520 | D9: =Historicals!D27 -> 14010 | E9: =Historicals!E27 -> 38601 | F9: =Historicals!F27 -> 35837 | G9: =Historicals!G27 -> 36524 | H9: =Historicals!H27 -> 13515 | I9: =Historicals!I27 -> 37295 | J9: =Historicals!J27 -> 39209 | K9: =(Inputs!$E$70-I9-J9)*Inputs!$E$38 -> 35697.6 | L9: =Inputs!$E$70-I9-J9-K9 -> 23798.4 | M9: =$T9*Inputs!$E$39 -> 39306.937 | N9: =$T9*Inputs!$E$40 -> 40710.756 | O9: =$T9*Inputs!$E$41 -> 36499.299 | P9: =$T9*Inputs!$E$42 -> 23864.926 | R9: =SUM(E9:H9) -> 124477 | S9: =SUM(I9:L9) -> 136000 | T9: =T6*(1+Inputs!$E$71) -> 140381.92 | U9: =U6*(1+Inputs!$E$72) -> 138992 | V9: =V6*(1+Inputs!$E$73) -> 138992
A10: Shipment growth YoY | B10: % | G10: =G9/C9-1 -> 0.32718023 | H10: =H9/D9-1 -> -0.035331906 | I10: =I9/E9-1 -> -0.03383332 | J10: =J9/F9-1 -> 0.094092697 | K10: =K9/G9-1 -> -0.022626218 | L10: =L9/H9-1 -> 0.7608879 | M10: =M9/I9-1 -> 0.053946565 | N10: =N9/J9-1 -> 0.038301317 | ... P10: =P9/L9-1 -> 0.0027954033 | S10: =S9/R9-1 -> 0.092571318 | T10: =T9/S9-1 -> 0.032219988 | U10: =U9/T9-1 -> -0.0099009901 | V10: =V9/U9-1 -> 0
A11: Implied dealer inventory change (shipments - retail) | B11: units | C11: =C9-C6 -> -8646 | D11: =D9-D6 -> -11650 | E11: =E9-E6 -> 7591 | F11: =F9-F6 -> -6417 | G11: =G9-G6 -> 2540 | H11: =H9-H6 -> -11772 | I11: =I9-I6 -> 3788 | J11: =J9-J6 -> -3258 | ... P11: =P9-P6 -> -2696.5387 | R11: =R9-R6 -> -8058 | S11: =S9-S6 -> -1615.84 | T11: =T9-T6 -> 1389.92 | U11: =U9-U6 -> 0 | V11: =V9-V6 -> 0
A12: Reported global dealer inventory, YoY | B12: % | G12: =Historicals!G36 -> -0.13 | H12: =Historicals!H36 -> -0.17 | I12: =Historicals!I36 -> -0.22 | J12: =Historicals!J36 -> -0.17
A13: Sport & Lightweight share of shipments | B13: % | C13: =Historicals!C30/Historicals!C27 -> 0.06431686 | D13: =Historicals!D30/Historicals!D27 -> 0.1076374 | E13: =Historicals!E30/Historicals!E27 -> 0.054609984 | F13: =Historicals!F30/Historicals!F27 -> 0.088958339 | G13: =Historicals!G30/Historicals!G27 -> 0.071952689 | H13: =Historicals!H30/Historicals!H27 -> 0.12682205 | I13: =Historicals!I30/Historicals!I27 -> 0.10004022 | J13: =Historicals!J30/Historicals!J27 -> 0.11775358
A14: Touring share of shipments | B14: % | C14: =Historicals!C28/Historicals!C27 -> 0.56297238 | D14: =Historicals!D28/Historicals!D27 -> 0.39707352 | E14: =Historicals!E28/Historicals!E27 -> 0.6134038 | F14: =Historicals!F28/Historicals!F27 -> 0.50450652 | G14: =Historicals!G28/Historicals!G27 -> 0.60330194 | H14: =Historicals!H28/Historicals!H27 -> 0.40392157 | I14: =Historicals!I28/Historicals!I27 -> 0.57702105 | J14: =Historicals!J28/Historicals!J27 -> 0.50093091
A16: Income statement
A17: Motorcycle revenue per unit | B17: $000 | C17: =Historicals!C6/Historicals!C27 -> 22.370203 | D17: =Historicals!D6/Historicals!D27 -> 16.52177 | E17: =Historicals!E6/Historicals!E27 -> 22.379291 | F17: =Historicals!F6/Historicals!F27 -> 21.71083 | G17: =Historicals!G6/Historicals!G27 -> 22.502026 | H17: =Historicals!H6/Historicals!H27 -> 14.34569 | I17: =Historicals!I6/Historicals!I27 -> 22.423757 | J17: =Historicals!J6/Historicals!J27 -> 21.629141 | K17: =Inputs!$E$60*(1+Inputs!$E$74) -> 22.016509 | L17: =Inputs!$E$60*(1+Inputs!$E$74) -> 22.016509 | M17: =$K17*(1+Inputs!$E$75) -> 21.796344 | N17: =$K17*(1+Inputs!$E$75) -> 21.796344 | O17: =$K17*(1+Inputs!$E$75) -> 21.796344 | P17: =$K17*(1+Inputs!$E$75) -> 21.796344 | R17: =R18/R9*1000 -> 21.350611 | S17: =S18/S9*1000 -> 22.016509 | T17: =T18/T9*1000 -> 21.796344 | U17: =T17*(1+Inputs!$E$76) -> 21.796344 | V17: =U17*(1+Inputs!$E$77) -> 22.014307
A18: HDMC - Motorcycles revenue | B18: $m | C18: =Historicals!C6/1000 -> 615.628 | D18: =Historicals!D6/1000 -> 231.47 | E18: =Historicals!E6/1000 -> 863.863 | F18: =Historicals!F6/1000 -> 778.051 | G18: =Historicals!G6/1000 -> 821.864 | H18: =Historicals!H6/1000 -> 193.882 | I18: =Historicals!I6/1000 -> 836.294 | J18: =Historicals!J6/1000 -> 848.057 | K18: =K9*K17/1000 -> 785.93653 | L18: =L9*L17/1000 -> 523.95769 | M18: =M9*M17/1000 -> 856.74752 | N18: =N9*N17/1000 -> 887.34564 | O18: =O9*O17/1000 -> 795.55127 | P18: =P9*P17/1000 -> 520.16814 | R18: =SUM(E18:H18) -> 2657.66 | S18: =SUM(I18:L18) -> 2994.2452 | T18: =SUM(M18:P18) -> 3059.8126 | U18: =U9*U17/1000 -> 3029.5174 | V18: =V9*V17/1000 -> 3059.8126
A19: HDMC - Parts & accessories | B19: $m | C19: =(Historicals!C7)/1000 -> 174.301 | D19: =(Historicals!D7)/1000 -> 117.605 | E19: =(Historicals!E7)/1000 -> 143.433 | F19: =(Historicals!F7)/1000 -> 186.874 | G19: =(Historicals!G7)/1000 -> 167.252 | H19: =(Historicals!H7)/1000 -> 116.513 | I19: =(Historicals!I7)/1000 -> 142.243 | J19: =(Historicals!J7)/1000 -> 176.95 | K19: =G19*(1+Inputs!$E$78) -> 165.57948 | L19: =H19*(1+Inputs!$E$78) -> 115.34787 | M19: =I19*(1+Inputs!$E$78) -> 140.82057 | N19: =J19*(1+Inputs!$E$78) -> 175.1805 | O19: =K19*(1+Inputs!$E$78) -> 163.92369 | P19: =L19*(1+Inputs!$E$78) -> 114.19439 | R19: =SUM(E19:H19) -> 614.072 | S19: =SUM(I19:L19) -> 600.12035 | T19: =SUM(M19:P19) -> 594.11915 | U19: =T19*(1+Inputs!$E$78) -> 588.17796 | V19: =U19*(1+Inputs!$E$78) -> 582.29618
A20: HDMC - Apparel, licensing & other | B20: $m | C20: =(Historicals!C8+Historicals!C9+Historicals!C10)/1000 -> 86.476 | D20: =(Historicals!D8+Historicals!D9+Historicals!D10)/1000 -> 71.414 | E20: =(Historicals!E8+Historicals!E9+Historicals!E10)/1000 -> 74.209 | F20: =(Historicals!F8+Historicals!F9+Historicals!F10)/1000 -> 78.724 | G20: =(Historicals!G8+Historicals!G9+Historicals!G10)/1000 -> 84.843 | H20: =(Historicals!H8+Historicals!H9+Historicals!H10)/1000 -> 68.8 | I20: =(Historicals!I8+Historicals!I9+Historicals!I10)/1000 -> 76.934 | J20: =(Historicals!J8+Historicals!J9+Historicals!J10)/1000 -> 79.273 | K20: =G20*(1+Inputs!$E$78) -> 83.99457 | L20: =H20*(1+Inputs!$E$78) -> 68.112 | M20: =I20*(1+Inputs!$E$78) -> 76.16466 | N20: =J20*(1+Inputs!$E$78) -> 78.48027 | O20: =K20*(1+Inputs!$E$78) -> 83.154624 | P20: =L20*(1+Inputs!$E$78) -> 67.43088 | R20: =SUM(E20:H20) -> 306.576 | S20: =SUM(I20:L20) -> 308.31357 | T20: =SUM(M20:P20) -> 305.23043 | U20: =T20*(1+Inputs!$E$78) -> 302.17813 | V20: =U20*(1+Inputs!$E$78) -> 299.15635
A21: HDMC revenue | B21: $m | C21: =C18+C19+C20 -> 876.405 | D21: =D18+D19+D20 -> 420.489 | E21: =E18+E19+E20 -> 1081.505 | F21: =F18+F19+F20 -> 1043.649 | G21: =G18+G19+G20 -> 1073.959 | H21: =H18+H19+H20 -> 379.195 | I21: =I18+I19+I20 -> 1055.471 | J21: =J18+J19+J20 -> 1104.28 | ... P21: =P18+P19+P20 -> 701.79341 | R21: =R18+R19+R20 -> 3578.308 | S21: =S18+S19+S20 -> 3902.6791 | T21: =T18+T19+T20 -> 3959.1621 | U21: =U18+U19+U20 -> 3919.8735 | V21: =V18+V19+V20 -> 3941.2651
A22: HDMC revenue growth YoY | B22: % | G22: =G21/C21-1 -> 0.22541405 | H22: =H21/D21-1 -> -0.098204709 | I22: =I21/E21-1 -> -0.024072011 | J22: =J21/F21-1 -> 0.058095203 | K22: =K21/G21-1 -> -0.035800641 | L22: =L21/H21-1 -> 0.86557723 | M22: =M21/I21-1 -> 0.017301989 | N22: =N21/J21-1 -> 0.033258244 | ... P22: =P21/L21-1 -> -0.007950254 | S22: =S21/R21-1 -> 0.090649306 | T22: =T21/S21-1 -> 0.01447288 | U22: =U21/T21-1 -> -0.0099234808 | V22: =V21/U21-1 -> 0.0054572203
A23: HDMC gross profit | B23: $m | C23: =Historicals!C11/1000 -> 263.813 | D23: =Historicals!D11/1000 -> -3.17 | E23: =Historicals!E11/1000 -> 315.244 | F23: =Historicals!F11/1000 -> 298.705 | G23: =Historicals!G11/1000 -> 283.11 | H23: =Historicals!H11/1000 -> -30.467 | I23: =Historicals!I11/1000 -> 266.989 | J23: =Historicals!J11/1000 -> 304.126 | K23: =(Inputs!$E$57+Inputs!$E$79)*K21-Inputs!$E$58*(1+Inputs!$E$43)^0 -> 271.44538 | L23: =(Inputs!$E$57+Inputs!$E$79)*L21-Inputs!$E$58*(1+Inputs!$E$43)^0 -> 119.72584 | M23: =(Inputs!$E$57+Inputs!$E$80)*M21-Inputs!$E$58*(1+Inputs!$E$43)^1 -> 284.97232 | N23: =(Inputs!$E$57+Inputs!$E$80)*N21-Inputs!$E$58*(1+Inputs!$E$43)^1 -> 316.08157 | O23: =(Inputs!$E$57+Inputs!$E$80)*O21-Inputs!$E$58*(1+Inputs!$E$43)^1 -> 270.58932 | P23: =(Inputs!$E$57+Inputs!$E$80)*P21-Inputs!$E$58*(1+Inputs!$E$43)^1 -> 112.97699 | R23: =SUM(E23:H23) -> 866.592 | S23: =SUM(I23:L23) -> 962.28622 | T23: =SUM(M23:P23) -> 984.6202 | U23: =(Inputs!$E$57+Inputs!$E$80)*U21-4*Inputs!$E$58*(1+Inputs!$E$43)^2 -> 949.52782 | V23: =(Inputs!$E$57+Inputs!$E$80)*V21-4*Inputs!$E$58*(1+Inputs!$E$43)^3 -> 942.15725
A24: HDMC gross margin | B24: % | C24: =C23/C21 -> 0.30101722 | D24: =D23/D21 -> -0.0075388417 | E24: =E23/E21 -> 0.2914864 | F24: =F23/F21 -> 0.28621213 | G24: =G23/G21 -> 0.26361342 | H24: =H23/H21 -> -0.080346524 | I24: =I23/I21 -> 0.25295721 | J24: =J23/J21 -> 0.2754066 | ... P24: =P23/P21 -> 0.16098325 | R24: =R23/R21 -> 0.24217926 | S24: =S23/S21 -> 0.24657067 | T24: =T23/T21 -> 0.24869408 | U24: =U23/U21 -> 0.2422343 | V24: =V23/V21 -> 0.23904945
A25: HDMC operating expense | B25: $m | C25: =Historicals!C12/1000 -> 208.676 | D25: =Historicals!D12/1000 -> 210.472 | E25: =Historicals!E12/1000 -> 198.972 | F25: =Historicals!F12/1000 -> 237.389 | G25: =Historicals!G12/1000 -> 228.991 | H25: =Historicals!H12/1000 -> 229.97 | I25: =Historicals!I12/1000 -> 248.064 | J25: =Historicals!J12/1000 -> 231.788 | K25: =G25*(1+Inputs!$E$81) -> 231.28091 | L25: =H25*(1+Inputs!$E$81) -> 232.2697 | M25: =I25*(1+Inputs!$E$81) -> 250.54464 | N25: =J25*(1+Inputs!$E$81) -> 234.10588 | O25: =K25*(1+Inputs!$E$81) -> 233.59372 | P25: =L25*(1+Inputs!$E$81) -> 234.5924 | R25: =SUM(E25:H25) -> 895.322 | S25: =SUM(I25:L25) -> 943.40261 | T25: =SUM(M25:P25) -> 952.83664 | U25: =T25*(1+Inputs!$E$81) -> 962.365 | V25: =U25*(1+Inputs!$E$81) -> 971.98865
A26: HDMC operating income | B26: $m | C26: =C23-C25 -> 55.137 | D26: =D23-D25 -> -213.642 | E26: =E23-E25 -> 116.272 | F26: =F23-F25 -> 61.316 | G26: =G23-G25 -> 54.119 | H26: =H23-H25 -> -260.437 | I26: =I23-I25 -> 18.925 | J26: =J23-J25 -> 72.338 | ... P26: =P23-P25 -> -121.61541 | R26: =R23-R25 -> -28.73 | S26: =S23-S25 -> 18.883607 | T26: =T23-T25 -> 31.78356 | U26: =U23-U25 -> -12.837184 | V26: =V23-V25 -> -29.831406
A27: HDMC operating margin | B27: % | C27: =C26/C21 -> 0.062912694 | D27: =D26/D21 -> -0.50807988 | E27: =E26/E21 -> 0.10750944 | F27: =F26/F21 -> 0.058751553 | G27: =G26/G21 -> 0.050392054 | H27: =H26/H21 -> -0.68681549 | I27: =I26/I21 -> 0.017930384 | J27: =J26/J21 -> 0.065506937 | ... P27: =P26/P21 -> -0.17329232 | R27: =R26/R21 -> -0.0080289343 | S27: =S26/S21 -> 0.0048386265 | T27: =T26/T21 -> 0.0080278502 | U27: =U26/U21 -> -0.0032748974 | V27: =V26/V21 -> -0.0075689926
A28: LiveWire revenue | B28: $m | C28: =Historicals!C13/1000 -> 4.808 | D28: =Historicals!D13/1000 -> 10.4 | E28: =Historicals!E13/1000 -> 2.743 | F28: =Historicals!F13/1000 -> 6.011 | G28: =Historicals!G13/1000 -> 5.563 | H28: =Historicals!H13/1000 -> 11.354 | I28: =Historicals!I13/1000 -> 5.116 | J28: =Historicals!J13/1000 -> 9.114 | K28: =G28*(1+Inputs!$E$86) -> 6.6756 | L28: =H28*(1+Inputs!$E$86) -> 13.6248 | M28: =I28*(1+Inputs!$E$86) -> 6.1392 | N28: =J28*(1+Inputs!$E$86) -> 10.9368 | O28: =K28*(1+Inputs!$E$86) -> 8.01072 | P28: =L28*(1+Inputs!$E$86) -> 16.34976 | R28: =SUM(E28:H28) -> 25.671 | S28: =SUM(I28:L28) -> 34.5304 | T28: =SUM(M28:P28) -> 41.43648 | U28: =T28*(1+Inputs!$E$86) -> 49.723776 | V28: =U28*(1+Inputs!$E$86) -> 59.668531
A29: LiveWire operating income (loss) | B29: $m | C29: =(Historicals!C14-Historicals!C15)/1000 -> -26.085 | D29: =(Historicals!D14-Historicals!D15)/1000 -> -26.146 | E29: =(Historicals!E14-Historicals!E15)/1000 -> -19.809 | F29: =(Historicals!F14-Historicals!F15)/1000 -> -18.653 | G29: =(Historicals!G14-Historicals!G15)/1000 -> -18.181 | H29: =(Historicals!H14-Historicals!H15)/1000 -> -18.374 | I29: =(Historicals!I14-Historicals!I15)/1000 -> -17.671 | J29: =(Historicals!J14-Historicals!J15)/1000 -> -17.927 | K29: =(Inputs!$E$82-I29-J29)/2 -> -19.701 | L29: =(Inputs!$E$82-I29-J29)/2 -> -19.701 | M29: =Inputs!$E$83/4 -> -16.25 | N29: =Inputs!$E$83/4 -> -16.25 | O29: =Inputs!$E$83/4 -> -16.25 | P29: =Inputs!$E$83/4 -> -16.25 | R29: =SUM(E29:H29) -> -75.017 | S29: =SUM(I29:L29) -> -75 | T29: =SUM(M29:P29) -> -65 | U29: =Inputs!$E$84 -> -55 | V29: =Inputs!$E$85 -> -45
A30: HDFS revenue | B30: $m | C30: =Historicals!C16/1000 -> 269.482 | D30: =Historicals!D16/1000 -> 256.72 | E30: =Historicals!E16/1000 -> 244.961 | F30: =Historicals!F16/1000 -> 257.438 | G30: =Historicals!G16/1000 -> 261.188 | H30: =Historicals!H16/1000 -> 105.609 | I30: =Historicals!I16/1000 -> 111.944 | J30: =Historicals!J16/1000 -> 117.043 | K30: =AVERAGE($I30:$J30)*(1+Inputs!$E$91)^0.5 -> 116.19821 | L30: =AVERAGE($I30:$J30)*(1+Inputs!$E$91)^0.5 -> 116.19821 | M30: =AVERAGE($I30:$J30)*(1+Inputs!$E$91)^1.5 -> 119.68416 | N30: =AVERAGE($I30:$J30)*(1+Inputs!$E$91)^1.5 -> 119.68416 | O30: =AVERAGE($I30:$J30)*(1+Inputs!$E$91)^1.5 -> 119.68416 | P30: =AVERAGE($I30:$J30)*(1+Inputs!$E$91)^1.5 -> 119.68416 | R30: =SUM(E30:H30) -> 869.196 | S30: =SUM(I30:L30) -> 461.38342 | T30: =SUM(M30:P30) -> 478.73663 | U30: =T30*(1+Inputs!$E$91) -> 493.09873 | V30: =U30*(1+Inputs!$E$91) -> 507.89169
A31: HDFS operating income | B31: $m | C31: =Historicals!C17/1000 -> 76.744 | D31: =Historicals!D17/1000 -> 46.44 | E31: =Historicals!E17/1000 -> 64.036 | F31: =Historicals!F17/1000 -> 69.773 | G31: =Historicals!G17/1000 -> 438.82 | H31: =Historicals!H17/1000 -> -82.247 | I31: =Historicals!I17/1000 -> 22.24 | J31: =Historicals!J17/1000 -> 21.599 | K31: =(Inputs!$E$87-I31-J31)/2 -> 8.0805 | L31: =(Inputs!$E$87-I31-J31)/2 -> 8.0805 | M31: =Inputs!$E$88/4 -> 16.25 | N31: =Inputs!$E$88/4 -> 16.25 | O31: =Inputs!$E$88/4 -> 16.25 | P31: =Inputs!$E$88/4 -> 16.25 | R31: =SUM(E31:H31) -> 490.382 | S31: =SUM(I31:L31) -> 60 | T31: =SUM(M31:P31) -> 65 | U31: =Inputs!$E$89 -> 70 | V31: =Inputs!$E$90 -> 72
A32: Total revenue | B32: $m | C32: =C21+C28+C30 -> 1150.695 | D32: =D21+D28+D30 -> 687.609 | E32: =E21+E28+E30 -> 1329.209 | F32: =F21+F28+F30 -> 1307.098 | G32: =G21+G28+G30 -> 1340.71 | H32: =H21+H28+H30 -> 496.158 | I32: =I21+I28+I30 -> 1172.531 | J32: =J21+J28+J30 -> 1230.437 | ... P32: =P21+P28+P30 -> 837.82733 | R32: =R21+R28+R30 -> 4473.175 | S32: =S21+S28+S30 -> 4398.593 | T32: =T21+T28+T30 -> 4479.3353 | U32: =U21+U28+U30 -> 4462.696 | V32: =V21+V28+V30 -> 4508.8253
A33: Consolidated operating income | B33: $m | C33: =C26+C29+C31 -> 105.796 | D33: =D26+D29+D31 -> -193.348 | E33: =E26+E29+E31 -> 160.499 | F33: =F26+F29+F31 -> 112.436 | G33: =G26+G29+G31 -> 474.758 | H33: =H26+H29+H31 -> -361.058 | I33: =I26+I29+I31 -> 23.494 | J33: =J26+J29+J31 -> 76.01 | ... P33: =P26+P29+P31 -> -121.61541 | R33: =R26+R29+R31 -> 386.635 | S33: =S26+S29+S31 -> 3.8836068 | T33: =T26+T29+T31 -> 31.78356 | U33: =U26+U29+U31 -> 2.1628164 | V33: =V26+V29+V31 -> -2.8314064
A34: Other income, net | B34: $m | C34: =Historicals!C18/1000 -> 18.408 | D34: =Historicals!D18/1000 -> 17.445 | E34: =Historicals!E18/1000 -> 16.273 | F34: =Historicals!F18/1000 -> 14.477 | G34: =Historicals!G18/1000 -> 14.706 | H34: =Historicals!H18/1000 -> 15.814 | I34: =Historicals!I18/1000 -> 13.477 | J34: =Historicals!J18/1000 -> 11.047 | K34: =Inputs!$E$30 -> 12 | L34: =Inputs!$E$30 -> 12 | M34: =Inputs!$E$30 -> 12 | N34: =Inputs!$E$30 -> 12 | O34: =Inputs!$E$30 -> 12 | P34: =Inputs!$E$30 -> 12 | R34: =SUM(E34:H34) -> 61.27 | S34: =SUM(I34:L34) -> 48.524 | T34: =SUM(M34:P34) -> 48 | U34: =4*Inputs!$E$30 -> 48 | V34: =4*Inputs!$E$30 -> 48
A35: Investment income | B35: $m | C35: =Historicals!C19/1000 -> 16.45 | D35: =Historicals!D19/1000 -> 13.3 | E35: =Historicals!E19/1000 -> 8.941 | F35: =Historicals!F19/1000 -> 10.95 | G35: =Historicals!G19/1000 -> 12.267 | H35: =Historicals!H19/1000 -> 12.112 | I35: =Historicals!I19/1000 -> 8.696 | J35: =Historicals!J19/1000 -> 11.84 | K35: =Inputs!$E$31 -> 9 | L35: =Inputs!$E$31 -> 9 | M35: =Inputs!$E$31 -> 9 | N35: =Inputs!$E$31 -> 9 | O35: =Inputs!$E$31 -> 9 | P35: =Inputs!$E$31 -> 9 | R35: =SUM(E35:H35) -> 44.27 | S35: =SUM(I35:L35) -> 38.536 | T35: =SUM(M35:P35) -> 36 | U35: =4*Inputs!$E$31 -> 36 | V35: =4*Inputs!$E$31 -> 36
A36: Interest expense | B36: $m | C36: =-Historicals!C20/1000 -> -7.707 | D36: =-Historicals!D20/1000 -> -7.683 | E36: =-Historicals!E20/1000 -> -7.686 | F36: =-Historicals!F20/1000 -> -7.696 | G36: =-Historicals!G20/1000 -> -10.182 | H36: =-Historicals!H20/1000 -> -7.88 | I36: =-Historicals!I20/1000 -> -3.57 | J36: =-Historicals!J20/1000 -> -3.622 | K36: =-Inputs!$E$32 -> -3.6 | L36: =-Inputs!$E$32 -> -3.6 | M36: =-Inputs!$E$32 -> -3.6 | N36: =-Inputs!$E$32 -> -3.6 | O36: =-Inputs!$E$32 -> -3.6 | P36: =-Inputs!$E$32 -> -3.6 | R36: =SUM(E36:H36) -> -33.444 | S36: =SUM(I36:L36) -> -14.392 | T36: =SUM(M36:P36) -> -14.4 | U36: =-4*Inputs!$E$32 -> -14.4 | V36: =-4*Inputs!$E$32 -> -14.4
A37: Pre-tax income | B37: $m | C37: =C33+C34+C35+C36 -> 132.947 | D37: =D33+D34+D35+D36 -> -170.286 | E37: =E33+E34+E35+E36 -> 178.027 | F37: =F33+F34+F35+F36 -> 130.167 | G37: =G33+G34+G35+G36 -> 491.549 | H37: =H33+H34+H35+H36 -> -341.012 | I37: =I33+I34+I35+I36 -> 42.097 | J37: =J33+J34+J35+J36 -> 95.275 | ... P37: =P33+P34+P35+P36 -> -104.21541 | R37: =R33+R34+R35+R36 -> 458.731 | S37: =S33+S34+S35+S36 -> 76.551607 | T37: =T33+T34+T35+T36 -> 101.38356 | U37: =U33+U34+U35+U36 -> 71.762816 | V37: =V33+V34+V35+V36 -> 66.768594
A38: Income tax | B38: $m | C38: =-Historicals!C21/1000 -> -16.98 | D38: =-Historicals!D21/1000 -> 51.857 | E38: =-Historicals!E21/1000 -> -47.23 | F38: =-Historicals!F21/1000 -> -24.422 | G38: =-Historicals!G21/1000 -> -116.384 | H38: =-Historicals!H21/1000 -> 58.459 | I38: =-Historicals!I21/1000 -> -17.974 | J38: =-Historicals!J21/1000 -> -16.294 | K38: =-K37*Inputs!$E$29 -> -10.567113 | L38: =-L37*Inputs!$E$29 -> 24.555804 | M38: =-M37*Inputs!$E$29 -> -11.920365 | N38: =-N37*Inputs!$E$29 -> -22.856409 | O38: =-O37*Inputs!$E$29 -> -12.510989 | P38: =-P37*Inputs!$E$29 -> 23.969544 | R38: =SUM(E38:H38) -> -129.577 | S38: =SUM(I38:L38) -> -20.27931 | T38: =SUM(M38:P38) -> -23.318219 | U38: =-U37*Inputs!$E$29 -> -16.505448 | V38: =-V37*Inputs!$E$29 -> -15.356777
A39: Net income (incl. NCI) | B39: $m | C39: =C37+C38 -> 115.967 | D39: =D37+D38 -> -118.429 | E39: =E37+E38 -> 130.797 | F39: =F37+F38 -> 105.745 | G39: =G37+G38 -> 375.165 | H39: =H37+H38 -> -282.553 | I39: =I37+I38 -> 24.123 | J39: =J37+J38 -> 78.981 | ... P39: =P37+P38 -> -80.245866 | R39: =R37+R38 -> 329.154 | S39: =S37+S38 -> 56.272297 | T39: =T37+T38 -> 78.065342 | U39: =U37+U38 -> 55.257369 | V39: =V37+V38 -> 51.411817
A40: Add: loss attributable to NCI | B40: $m | C40: =Historicals!C22/1000 -> 3.073 | D40: =Historicals!D22/1000 -> 1.538 | E40: =Historicals!E22/1000 -> 2.307 | F40: =Historicals!F22/1000 -> 1.824 | G40: =Historicals!G22/1000 -> 2.201 | H40: =Historicals!H22/1000 -> 3.252 | I40: =Historicals!I22/1000 -> 0.65 | J40: =Historicals!J22/1000 -> 0.824 | K40: =-K29*Inputs!$E$35 -> 0.98505 | L40: =-L29*Inputs!$E$35 -> 0.98505 | M40: =-M29*Inputs!$E$35 -> 0.8125 | N40: =-N29*Inputs!$E$35 -> 0.8125 | O40: =-O29*Inputs!$E$35 -> 0.8125 | P40: =-P29*Inputs!$E$35 -> 0.8125 | R40: =SUM(E40:H40) -> 9.584 | S40: =SUM(I40:L40) -> 3.4441 | T40: =SUM(M40:P40) -> 3.25 | U40: =-U29*Inputs!$E$35 -> 2.75 | V40: =-V29*Inputs!$E$35 -> 2.25
A41: Net income attributable to HOG | B41: $m | C41: =C39+C40 -> 119.04 | D41: =D39+D40 -> -116.891 | E41: =E39+E40 -> 133.104 | F41: =F39+F40 -> 107.569 | G41: =G39+G40 -> 377.366 | H41: =H39+H40 -> -279.301 | I41: =I39+I40 -> 24.773 | J41: =J39+J40 -> 79.805 | ... P41: =P39+P40 -> -79.433366 | R41: =R39+R40 -> 338.738 | S41: =S39+S40 -> 59.716397 | T41: =T39+T40 -> 81.315342 | U41: =U39+U40 -> 58.007369 | V41: =V39+V40 -> 53.661817
A42: Diluted shares | B42: m | C42: =Historicals!C23/1000 -> 130.963 | D42: =Historicals!D23/1000 -> 126.264 | E42: =Historicals!E23/1000 -> 124.724 | F42: =Historicals!F23/1000 -> 122.203 | G42: =Historicals!G23/1000 -> 121.676 | H42: =Historicals!H23/1000 -> 114.311 | I42: =Historicals!I23/1000 -> 110.768 | J42: =Historicals!J23/1000 -> 108.568 | K42: =J42-Inputs!$E$92/Inputs!$E$5 -> 107.08377 | L42: =K42-Inputs!$E$92/Inputs!$E$5 -> 105.59954 | M42: =L42-Inputs!$E$92/Inputs!$E$5 -> 104.11531 | N42: =M42-Inputs!$E$92/Inputs!$E$5 -> 102.63108 | O42: =N42-Inputs!$E$92/Inputs!$E$5 -> 101.14685 | P42: =O42-Inputs!$E$92/Inputs!$E$5 -> 99.66262 | R42: =AVERAGE(E42:H42) -> 120.7285 | S42: =AVERAGE(I42:L42) -> 108.00483 | T42: =AVERAGE(M42:P42) -> 101.88896 | U42: =T42-4*Inputs!$E$92/Inputs!$E$5 -> 95.952045 | V42: =U42-4*Inputs!$E$92/Inputs!$E$5 -> 90.015124
...

Sheet Bear
A1: Harley-Davidson (HOG) - integrated model: BEAR CASE ($ millions unless noted)
A2: Blue = reported | Black = formula | Red = assumption (see Inputs) | Purple = consensus/market. Shaded columns = forecast.
C4: Q3'24 | D4: Q4'24 | E4: Q1'25 | F4: Q2'25 | G4: Q3'25 | H4: Q4'25 | I4: Q1'26 | J4: Q2'26 | K4: Q3'26E | L4: Q4'26E | M4: Q1'27E | N4: Q2'27E | O4: Q3'27E | P4: Q4'27E | R4: FY2025A | S4: FY2026E | T4: FY2027E | U4: FY2028E | V4: FY2029E
A5: Unit drivers
A6: Retail sales - worldwide | B6: units | C6: =Historicals!C32+Historicals!C33+Historicals!C34+Historicals!C35 -> 36166 | D6: =Historicals!D32+Historicals!D33+Historicals!D34+Historicals!D35 -> 25660 | E6: =Historicals!E32+Historicals!E33+Historicals!E34+Historicals!E35 -> 31010 | F6: =Historicals!F32+Historicals!F33+Historicals!F34+Historicals!F35 -> 42254 | G6: =Historicals!G32+Historicals!G33+Historicals!G34+Historicals!G35 -> 33984 | H6: =Historicals!H32+Historicals!H33+Historicals!H34+Historicals!H35 -> 25287 | I6: =Historicals!I32+Historicals!I33+Historicals!I34+Historicals!I35 -> 33507 | J6: =Historicals!J32+Historicals!J33+Historicals!J34+Historicals!J35 -> 42467 | K6: =G6*(1+Inputs!$D$66) -> 32964.48 | L6: =H6*(1+Inputs!$D$66) -> 24528.39 | M6: =I6*(1+Inputs!$D$67) -> 31831.65 | N6: =J6*(1+Inputs!$D$67) -> 40343.65 | O6: =K6*(1+Inputs!$D$67) -> 31316.256 | P6: =L6*(1+Inputs!$D$67) -> 23301.97 | R6: =SUM(E6:H6) -> 132535 | S6: =SUM(I6:L6) -> 133466.87 | T6: =SUM(M6:P6) -> 126793.53 | U6: =T6*(1+Inputs!$D$68) -> 122989.72 | V6: =U6*(1+Inputs!$D$69) -> 120529.93
A7: of which North America | B7: units | C7: =Historicals!C32 -> 24573 | D7: =Historicals!D32 -> 15127 | E7: =Historicals!E32 -> 20892 | F7: =Historicals!F32 -> 28931 | G7: =Historicals!G32 -> 23462 | H7: =Historicals!H32 -> 15847 | I7: =Historicals!I32 -> 23803 | J7: =Historicals!J32 -> 29751 | R7: =SUM(E7:H7) -> 89132
A8: Retail growth YoY | B8: % | G8: =G6/C6-1 -> -0.060332909 | H8: =H6/D6-1 -> -0.014536243 | I8: =I6/E6-1 -> 0.080522412 | J8: =J6/F6-1 -> 0.0050409429 | K8: =K6/G6-1 -> -0.03 | L8: =L6/H6-1 -> -0.03 | M8: =M6/I6-1 -> -0.05 | N8: =N6/J6-1 -> -0.05 | ... P8: =P6/L6-1 -> -0.05 | S8: =S6/R6-1 -> 0.0070311239 | T8: =T6/S6-1 -> -0.05 | U8: =U6/T6-1 -> -0.03 | V8: =V6/U6-1 -> -0.02
A9: HDMC shipments - worldwide | B9: units | C9: =Historicals!C27 -> 27520 | D9: =Historicals!D27 -> 14010 | E9: =Historicals!E27 -> 38601 | F9: =Historicals!F27 -> 35837 | G9: =Historicals!G27 -> 36524 | H9: =Historicals!H27 -> 13515 | I9: =Historicals!I27 -> 37295 | J9: =Historicals!J27 -> 39209 | K9: =(Inputs!$D$70-I9-J9)*Inputs!$E$38 -> 32097.6 | L9: =Inputs!$D$70-I9-J9-K9 -> 21398.4 | M9: =$T9*Inputs!$E$39 -> 34082.1 | N9: =$T9*Inputs!$E$40 -> 35299.318 | O9: =$T9*Inputs!$E$41 -> 31647.664 | P9: =$T9*Inputs!$E$42 -> 20692.704 | R9: =SUM(E9:H9) -> 124477 | S9: =SUM(I9:L9) -> 130000 | T9: =T6*(1+Inputs!$D$71) -> 121721.79 | U9: =U6*(1+Inputs!$D$72) -> 121759.82 | V9: =V6*(1+Inputs!$D$73) -> 120529.93
A10: Shipment growth YoY | B10: % | G10: =G9/C9-1 -> 0.32718023 | H10: =H9/D9-1 -> -0.035331906 | I10: =I9/E9-1 -> -0.03383332 | J10: =J9/F9-1 -> 0.094092697 | K10: =K9/G9-1 -> -0.12119155 | L10: =L9/H9-1 -> 0.58330744 | M10: =M9/I9-1 -> -0.086148279 | N10: =N9/J9-1 -> -0.099713898 | ... P10: =P9/L9-1 -> -0.032978937 | S10: =S9/R9-1 -> 0.044369643 | T10: =T9/S9-1 -> -0.063678574 | U10: =U9/T9-1 -> 0.0003125 | V10: =V9/U9-1 -> -0.01010101
A11: Implied dealer inventory change (shipments - retail) | B11: units | C11: =C9-C6 -> -8646 | D11: =D9-D6 -> -11650 | E11: =E9-E6 -> 7591 | F11: =F9-F6 -> -6417 | G11: =G9-G6 -> 2540 | H11: =H9-H6 -> -11772 | I11: =I9-I6 -> 3788 | J11: =J9-J6 -> -3258 | ... P11: =P9-P6 -> -2609.267 | R11: =R9-R6 -> -8058 | S11: =S9-S6 -> -3466.87 | T11: =T9-T6 -> -5071.7411 | U11: =U9-U6 -> -1229.8972 | V11: =V9-V6 -> 0
A12: Reported global dealer inventory, YoY | B12: % | G12: =Historicals!G36 -> -0.13 | H12: =Historicals!H36 -> -0.17 | I12: =Historicals!I36 -> -0.22 | J12: =Historicals!J36 -> -0.17
A13: Sport & Lightweight share of shipments | B13: % | C13: =Historicals!C30/Historicals!C27 -> 0.06431686 | D13: =Historicals!D30/Historicals!D27 -> 0.1076374 | E13: =Historicals!E30/Historicals!E27 -> 0.054609984 | F13: =Historicals!F30/Historicals!F27 -> 0.088958339 | G13: =Historicals!G30/Historicals!G27 -> 0.071952689 | H13: =Historicals!H30/Historicals!H27 -> 0.12682205 | I13: =Historicals!I30/Historicals!I27 -> 0.10004022 | J13: =Historicals!J30/Historicals!J27 -> 0.11775358
A14: Touring share of shipments | B14: % | C14: =Historicals!C28/Historicals!C27 -> 0.56297238 | D14: =Historicals!D28/Historicals!D27 -> 0.39707352 | E14: =Historicals!E28/Historicals!E27 -> 0.6134038 | F14: =Historicals!F28/Historicals!F27 -> 0.50450652 | G14: =Historicals!G28/Historicals!G27 -> 0.60330194 | H14: =Historicals!H28/Historicals!H27 -> 0.40392157 | I14: =Historicals!I28/Historicals!I27 -> 0.57702105 | J14: =Historicals!J28/Historicals!J27 -> 0.50093091
A16: Income statement
A17: Motorcycle revenue per unit | B17: $000 | C17: =Historicals!C6/Historicals!C27 -> 22.370203 | D17: =Historicals!D6/Historicals!D27 -> 16.52177 | E17: =Historicals!E6/Historicals!E27 -> 22.379291 | F17: =Historicals!F6/Historicals!F27 -> 21.71083 | G17: =Historicals!G6/Historicals!G27 -> 22.502026 | H17: =Historicals!H6/Historicals!H27 -> 14.34569 | I17: =Historicals!I6/Historicals!I27 -> 22.423757 | J17: =Historicals!J6/Historicals!J27 -> 21.629141 | K17: =Inputs!$E$60*(1+Inputs!$D$74) -> 21.576179 | L17: =Inputs!$E$60*(1+Inputs!$D$74) -> 21.576179 | M17: =$K17*(1+Inputs!$D$75) -> 20.713132 | N17: =$K17*(1+Inputs!$D$75) -> 20.713132 | O17: =$K17*(1+Inputs!$D$75) -> 20.713132 | P17: =$K17*(1+Inputs!$D$75) -> 20.713132 | R17: =R18/R9*1000 -> 21.350611 | S17: =S18/S9*1000 -> 21.83531 | T17: =T18/T9*1000 -> 20.713132 | U17: =T17*(1+Inputs!$D$76) -> 20.298869 | V17: =U17*(1+Inputs!$D$77) -> 20.09588
A18: HDMC - Motorcycles revenue | B18: $m | C18: =Historicals!C6/1000 -> 615.628 | D18: =Historicals!D6/1000 -> 231.47 | E18: =Historicals!E6/1000 -> 863.863 | F18: =Historicals!F6/1000 -> 778.051 | G18: =Historicals!G6/1000 -> 821.864 | H18: =Historicals!H6/1000 -> 193.882 | I18: =Historicals!I6/1000 -> 836.294 | J18: =Historicals!J6/1000 -> 848.057 | K18: =K9*K17/1000 -> 692.54356 | L18: =L9*L17/1000 -> 461.6957 | M18: =M9*M17/1000 -> 705.94702 | N18: =N9*N17/1000 -> 731.15941 | O18: =O9*O17/1000 -> 655.52223 | P18: =P9*P17/1000 -> 428.61069 | R18: =SUM(E18:H18) -> 2657.66 | S18: =SUM(I18:L18) -> 2838.5903 | T18: =SUM(M18:P18) -> 2521.2394 | U18: =U9*U17/1000 -> 2471.5867 | V18: =V9*V17/1000 -> 2422.155
A19: HDMC - Parts & accessories | B19: $m | C19: =(Historicals!C7)/1000 -> 174.301 | D19: =(Historicals!D7)/1000 -> 117.605 | E19: =(Historicals!E7)/1000 -> 143.433 | F19: =(Historicals!F7)/1000 -> 186.874 | G19: =(Historicals!G7)/1000 -> 167.252 | H19: =(Historicals!H7)/1000 -> 116.513 | I19: =(Historicals!I7)/1000 -> 142.243 | J19: =(Historicals!J7)/1000 -> 176.95 | K19: =G19*(1+Inputs!$D$78) -> 158.8894 | L19: =H19*(1+Inputs!$D$78) -> 110.68735 | M19: =I19*(1+Inputs!$D$78) -> 135.13085 | N19: =J19*(1+Inputs!$D$78) -> 168.1025 | O19: =K19*(1+Inputs!$D$78) -> 150.94493 | P19: =L19*(1+Inputs!$D$78) -> 105.15298 | R19: =SUM(E19:H19) -> 614.072 | S19: =SUM(I19:L19) -> 588.76975 | T19: =SUM(M19:P19) -> 559.33126 | U19: =T19*(1+Inputs!$D$78) -> 531.3647 | V19: =U19*(1+Inputs!$D$78) -> 504.79646
A20: HDMC - Apparel, licensing & other | B20: $m | C20: =(Historicals!C8+Historicals!C9+Historicals!C10)/1000 -> 86.476 | D20: =(Historicals!D8+Historicals!D9+Historicals!D10)/1000 -> 71.414 | E20: =(Historicals!E8+Historicals!E9+Historicals!E10)/1000 -> 74.209 | F20: =(Historicals!F8+Historicals!F9+Historicals!F10)/1000 -> 78.724 | G20: =(Historicals!G8+Historicals!G9+Historicals!G10)/1000 -> 84.843 | H20: =(Historicals!H8+Historicals!H9+Historicals!H10)/1000 -> 68.8 | I20: =(Historicals!I8+Historicals!I9+Historicals!I10)/1000 -> 76.934 | J20: =(Historicals!J8+Historicals!J9+Historicals!J10)/1000 -> 79.273 | K20: =G20*(1+Inputs!$D$78) -> 80.60085 | L20: =H20*(1+Inputs!$D$78) -> 65.36 | M20: =I20*(1+Inputs!$D$78) -> 73.0873 | N20: =J20*(1+Inputs!$D$78) -> 75.30935 | O20: =K20*(1+Inputs!$D$78) -> 76.570808 | P20: =L20*(1+Inputs!$D$78) -> 62.092 | R20: =SUM(E20:H20) -> 306.576 | S20: =SUM(I20:L20) -> 302.16785 | T20: =SUM(M20:P20) -> 287.05946 | U20: =T20*(1+Inputs!$D$78) -> 272.70648 | V20: =U20*(1+Inputs!$D$78) -> 259.07116
A21: HDMC revenue | B21: $m | C21: =C18+C19+C20 -> 876.405 | D21: =D18+D19+D20 -> 420.489 | E21: =E18+E19+E20 -> 1081.505 | F21: =F18+F19+F20 -> 1043.649 | G21: =G18+G19+G20 -> 1073.959 | H21: =H18+H19+H20 -> 379.195 | I21: =I18+I19+I20 -> 1055.471 | J21: =J18+J19+J20 -> 1104.28 | ... P21: =P18+P19+P20 -> 595.85567 | R21: =R18+R19+R20 -> 3578.308 | S21: =S18+S19+S20 -> 3729.5279 | T21: =T18+T19+T20 -> 3367.6301 | U21: =U18+U19+U20 -> 3275.6579 | V21: =V18+V19+V20 -> 3186.0226
A22: HDMC revenue growth YoY | B22: % | G22: =G21/C21-1 -> 0.22541405 | H22: =H21/D21-1 -> -0.098204709 | I22: =I21/E21-1 -> -0.024072011 | J22: =J21/F21-1 -> 0.058095203 | K22: =K21/G21-1 -> -0.13215141 | L22: =L21/H21-1 -> 0.68183403 | M22: =M21/I21-1 -> -0.1338794 | N22: =N21/J21-1 -> -0.11746001 | ... P22: =P21/L21-1 -> -0.065680652 | S22: =S21/R21-1 -> 0.042260157 | T22: =T21/S21-1 -> -0.097035816 | U22: =U21/T21-1 -> -0.027310658 | V22: =V21/U21-1 -> -0.027364058
A23: HDMC gross profit | B23: $m | C23: =Historicals!C11/1000 -> 263.813 | D23: =Historicals!D11/1000 -> -3.17 | E23: =Historicals!E11/1000 -> 315.244 | F23: =Historicals!F11/1000 -> 298.705 | G23: =Historicals!G11/1000 -> 283.11 | H23: =Historicals!H11/1000 -> -30.467 | I23: =Historicals!I11/1000 -> 266.989 | J23: =Historicals!J11/1000 -> 304.126 | K23: =(Inputs!$E$57+Inputs!$D$79)*K21-Inputs!$E$58*(1+Inputs!$E$43)^0 -> 214.27444 | L23: =(Inputs!$E$57+Inputs!$D$79)*L21-Inputs!$E$58*(1+Inputs!$E$43)^0 -> 81.128934 | M23: =(Inputs!$E$57+Inputs!$D$80)*M21-Inputs!$E$58*(1+Inputs!$E$43)^1 -> 197.47125 | N23: =(Inputs!$E$57+Inputs!$D$80)*N21-Inputs!$E$58*(1+Inputs!$E$43)^1 -> 224.49866 | O23: =(Inputs!$E$57+Inputs!$D$80)*O21-Inputs!$E$58*(1+Inputs!$E$43)^1 -> 183.54406 | P23: =(Inputs!$E$57+Inputs!$D$80)*P21-Inputs!$E$58*(1+Inputs!$E$43)^1 -> 55.050531 | R23: =SUM(E23:H23) -> 866.592 | S23: =SUM(I23:L23) -> 866.51837 | T23: =SUM(M23:P23) -> 660.5645 | U23: =(Inputs!$E$57+Inputs!$D$80)*U21-4*Inputs!$E$58*(1+Inputs!$E$43)^2 -> 602.48934 | V23: =(Inputs!$E$57+Inputs!$D$80)*V21-4*Inputs!$E$58*(1+Inputs!$E$43)^3 -> 545.1213
A24: HDMC gross margin | B24: % | C24: =C23/C21 -> 0.30101722 | D24: =D23/D21 -> -0.0075388417 | E24: =E23/E21 -> 0.2914864 | F24: =F23/F21 -> 0.28621213 | G24: =G23/G21 -> 0.26361342 | H24: =H23/H21 -> -0.080346524 | I24: =I23/I21 -> 0.25295721 | J24: =J23/J21 -> 0.2754066 | ... P24: =P23/P21 -> 0.092389035 | R24: =R23/R21 -> 0.24217926 | S24: =S23/S21 -> 0.23233997 | T24: =T23/T21 -> 0.19615115 | U24: =U23/U21 -> 0.18392926 | V24: =V23/V21 -> 0.17109775
